2021-12-02 20:11:54,341 INFO    MainThread:36521 [wandb_setup.py:_flush():71] setting env: {}
2021-12-02 20:11:54,341 INFO    MainThread:36521 [wandb_setup.py:_flush():71] setting login settings: {}
2021-12-02 20:11:54,341 INFO    MainThread:36521 [wandb_setup.py:_flush():71] setting login settings: {}
2021-12-02 20:11:54,342 INFO    MainThread:36521 [wandb_init.py:_log_setup():371] Logging user logs to /geoinfo_vol1/home/z/h/zhao2/vit-keras/wandb/run-20211202_201154-2d7n9dwi/logs/debug.log
2021-12-02 20:11:54,342 INFO    MainThread:36521 [wandb_init.py:_log_setup():372] Logging internal logs to /geoinfo_vol1/home/z/h/zhao2/vit-keras/wandb/run-20211202_201154-2d7n9dwi/logs/debug-internal.log
2021-12-02 20:11:54,342 INFO    MainThread:36521 [wandb_init.py:init():404] calling init triggers
2021-12-02 20:11:54,342 INFO    MainThread:36521 [wandb_init.py:init():411] wandb.init called with sweep_config: {}
config: {}
2021-12-02 20:11:54,342 INFO    MainThread:36521 [wandb_init.py:init():449] starting backend
2021-12-02 20:11:54,342 INFO    MainThread:36521 [backend.py:_multiprocessing_setup():97] multiprocessing start_methods=fork,spawn,forkserver, using: spawn
2021-12-02 20:11:54,364 INFO    MainThread:36521 [backend.py:ensure_launched():199] starting backend process...
2021-12-02 20:11:54,379 INFO    MainThread:36521 [backend.py:ensure_launched():205] started backend process with pid: 36646
2021-12-02 20:11:54,381 INFO    MainThread:36521 [wandb_init.py:init():458] backend started and connected
2021-12-02 20:11:54,383 INFO    MainThread:36521 [wandb_init.py:init():519] updated telemetry
2021-12-02 20:11:54,426 INFO    MainThread:36521 [wandb_init.py:init():549] communicating current version
2021-12-02 20:11:59,428 INFO    MainThread:36521 [wandb_init.py:init():564] communicating run to backend with 30 second timeout
2021-12-02 20:11:59,451 ERROR   MainThread:36521 [wandb_init.py:init():944] error
Traceback (most recent call last):
  File "/geoinfo_vol1/home/z/h/zhao2/mambaforge/envs/myenv/lib/python3.7/site-packages/wandb/sdk/wandb_init.py", line 917, in init
    run = wi.init()
  File "/geoinfo_vol1/home/z/h/zhao2/mambaforge/envs/myenv/lib/python3.7/site-packages/wandb/sdk/wandb_init.py", line 565, in init
    ret = backend.interface.communicate_run(run, timeout=30)
  File "/geoinfo_vol1/home/z/h/zhao2/mambaforge/envs/myenv/lib/python3.7/site-packages/wandb/sdk/interface/interface.py", line 205, in communicate_run
    return self._communicate_run(run, timeout=timeout)
  File "/geoinfo_vol1/home/z/h/zhao2/mambaforge/envs/myenv/lib/python3.7/site-packages/wandb/sdk/interface/interface_queue.py", line 334, in _communicate_run
    resp = self._communicate(req, timeout=timeout)
  File "/geoinfo_vol1/home/z/h/zhao2/mambaforge/envs/myenv/lib/python3.7/site-packages/wandb/sdk/interface/interface_queue.py", line 232, in _communicate
    return self._communicate_async(rec, local=local).get(timeout=timeout)
  File "/geoinfo_vol1/home/z/h/zhao2/mambaforge/envs/myenv/lib/python3.7/site-packages/wandb/sdk/interface/interface_queue.py", line 237, in _communicate_async
    raise Exception("The wandb backend process has shutdown")
Exception: The wandb backend process has shutdown
